Microsoft Windows [Version 10.0.19041.985]
(c) Microsoft Corporation. All rights reserved.

C:\Users\Lenovo User\Desktop\Axsos\python_stack\django> python startproject  orm_project
python: can't open file 'startproject': [Errno 2] No such file or directory

C:\Users\Lenovo User\Desktop\Axsos\python_stack\django> python-admin startproject  orm_project
'python-admin' is not recognized as an internal or external command,
operable program or batch file.

C:\Users\Lenovo User\Desktop\Axsos\python_stack\django>cd..

C:\Users\Lenovo User\Desktop\Axsos\python_stack>cd my_environments

C:\Users\Lenovo User\Desktop\Axsos\python_stack\my_environments>call django_env/scripts/activate
(django_env) C:\Users\Lenovo User\Desktop\Axsos\python_stack\my_environments> cd..

(django_env) C:\Users\Lenovo User\Desktop\Axsos\python_stack>cd django

(django_env) C:\Users\Lenovo User\Desktop\Axsos\python_stack\django>django-admin startproject orm_project

(django_env) C:\Users\Lenovo User\Desktop\Axsos\python_stack\django>python manage.py startapp orm_app
python: can't open file 'manage.py': [Errno 2] No such file or directory

(django_env) C:\Users\Lenovo User\Desktop\Axsos\python_stack\django>cd orm_project

(django_env) C:\Users\Lenovo User\Desktop\Axsos\python_stack\django\orm_project>python manage.py startapp orm_app

(django_env) C:\Users\Lenovo User\Desktop\Axsos\python_stack\django\orm_project> code.
'code.' is not recognized as an internal or external command,
operable program or batch file.

(django_env) C:\Users\Lenovo User\Desktop\Axsos\python_stack\django\orm_project>code .

(django_env) C:\Users\Lenovo User\Desktop\Axsos\python_stack\django\orm_project>python manage.py makemigrations
Traceback (most recent call last):
  File "manage.py", line 21, in <module>
    main()
  File "manage.py", line 17, in main
    execute_from_command_line(sys.argv)
  File "C:\Users\Lenovo User\Desktop\Axsos\python_stack\my_environments\django_env\lib\site-packages\django\core\management\__init__.py", line 381, in execute_from_command_line
    utility.execute()
  File "C:\Users\Lenovo User\Desktop\Axsos\python_stack\my_environments\django_env\lib\site-packages\django\core\management\__init__.py", line 357, in execute
    django.setup()
  File "C:\Users\Lenovo User\Desktop\Axsos\python_stack\my_environments\django_env\lib\site-packages\django\__init__.py", line 24, in setup
    apps.populate(settings.INSTALLED_APPS)
  File "C:\Users\Lenovo User\Desktop\Axsos\python_stack\my_environments\django_env\lib\site-packages\django\apps\registry.py", line 91, in populate
    app_config = AppConfig.create(entry)
  File "C:\Users\Lenovo User\Desktop\Axsos\python_stack\my_environments\django_env\lib\site-packages\django\apps\config.py", line 116, in create
    mod = import_module(mod_path)
  File "C:\Users\Lenovo User\AppData\Local\Programs\Python\Python36\lib\importlib\__init__.py", line 126, in import_module
    return _bootstrap._gcd_import(name[level:], package, level)
  File "<frozen importlib._bootstrap>", line 994, in _gcd_import
  File "<frozen importlib._bootstrap>", line 971, in _find_and_load
  File "<frozen importlib._bootstrap>", line 941, in _find_and_load_unlocked
  File "<frozen importlib._bootstrap>", line 219, in _call_with_frames_removed
  File "<frozen importlib._bootstrap>", line 994, in _gcd_import
  File "<frozen importlib._bootstrap>", line 971, in _find_and_load
  File "<frozen importlib._bootstrap>", line 953, in _find_and_load_unlocked
ModuleNotFoundError: No module named 'orm_appdjango'

(django_env) C:\Users\Lenovo User\Desktop\Axsos\python_stack\django\orm_project>python manage.py makemigrations
Traceback (most recent call last):
  File "manage.py", line 21, in <module>
    main()
  File "manage.py", line 17, in main
    execute_from_command_line(sys.argv)
  File "C:\Users\Lenovo User\Desktop\Axsos\python_stack\my_environments\django_env\lib\site-packages\django\core\management\__init__.py", line 381, in execute_from_command_line
    utility.execute()
  File "C:\Users\Lenovo User\Desktop\Axsos\python_stack\my_environments\django_env\lib\site-packages\django\core\management\__init__.py", line 357, in execute
    django.setup()
  File "C:\Users\Lenovo User\Desktop\Axsos\python_stack\my_environments\django_env\lib\site-packages\django\__init__.py", line 24, in setup
    apps.populate(settings.INSTALLED_APPS)
  File "C:\Users\Lenovo User\Desktop\Axsos\python_stack\my_environments\django_env\lib\site-packages\django\apps\registry.py", line 91, in populate
    app_config = AppConfig.create(entry)
  File "C:\Users\Lenovo User\Desktop\Axsos\python_stack\my_environments\django_env\lib\site-packages\django\apps\config.py", line 116, in create
    mod = import_module(mod_path)
  File "C:\Users\Lenovo User\AppData\Local\Programs\Python\Python36\lib\importlib\__init__.py", line 126, in import_module
    return _bootstrap._gcd_import(name[level:], package, level)
  File "<frozen importlib._bootstrap>", line 994, in _gcd_import
  File "<frozen importlib._bootstrap>", line 971, in _find_and_load
  File "<frozen importlib._bootstrap>", line 941, in _find_and_load_unlocked
  File "<frozen importlib._bootstrap>", line 219, in _call_with_frames_removed
  File "<frozen importlib._bootstrap>", line 994, in _gcd_import
  File "<frozen importlib._bootstrap>", line 971, in _find_and_load
  File "<frozen importlib._bootstrap>", line 953, in _find_and_load_unlocked
ModuleNotFoundError: No module named 'orm_appdjango'

(django_env) C:\Users\Lenovo User\Desktop\Axsos\python_stack\django\orm_project>python manage.py makemigrations \
Traceback (most recent call last):
  File "manage.py", line 21, in <module>
    main()
  File "manage.py", line 17, in main
    execute_from_command_line(sys.argv)
  File "C:\Users\Lenovo User\Desktop\Axsos\python_stack\my_environments\django_env\lib\site-packages\django\core\management\__init__.py", line 381, in execute_from_command_line
    utility.execute()
  File "C:\Users\Lenovo User\Desktop\Axsos\python_stack\my_environments\django_env\lib\site-packages\django\core\management\__init__.py", line 357, in execute
    django.setup()
  File "C:\Users\Lenovo User\Desktop\Axsos\python_stack\my_environments\django_env\lib\site-packages\django\__init__.py", line 24, in setup
    apps.populate(settings.INSTALLED_APPS)
  File "C:\Users\Lenovo User\Desktop\Axsos\python_stack\my_environments\django_env\lib\site-packages\django\apps\registry.py", line 91, in populate
    app_config = AppConfig.create(entry)
  File "C:\Users\Lenovo User\Desktop\Axsos\python_stack\my_environments\django_env\lib\site-packages\django\apps\config.py", line 116, in create
    mod = import_module(mod_path)
  File "C:\Users\Lenovo User\AppData\Local\Programs\Python\Python36\lib\importlib\__init__.py", line 126, in import_module
    return _bootstrap._gcd_import(name[level:], package, level)
  File "<frozen importlib._bootstrap>", line 994, in _gcd_import
  File "<frozen importlib._bootstrap>", line 971, in _find_and_load
  File "<frozen importlib._bootstrap>", line 941, in _find_and_load_unlocked
  File "<frozen importlib._bootstrap>", line 219, in _call_with_frames_removed
  File "<frozen importlib._bootstrap>", line 994, in _gcd_import
  File "<frozen importlib._bootstrap>", line 971, in _find_and_load
  File "<frozen importlib._bootstrap>", line 953, in _find_and_load_unlocked
ModuleNotFoundError: No module named 'orm_appdjango'

(django_env) C:\Users\Lenovo User\Desktop\Axsos\python_stack\django\orm_project>python manage.py makemigrations \
Traceback (most recent call last):
  File "manage.py", line 21, in <module>
    main()
  File "manage.py", line 17, in main
    execute_from_command_line(sys.argv)
  File "C:\Users\Lenovo User\Desktop\Axsos\python_stack\my_environments\django_env\lib\site-packages\django\core\management\__init__.py", line 381, in execute_from_command_line
    utility.execute()
  File "C:\Users\Lenovo User\Desktop\Axsos\python_stack\my_environments\django_env\lib\site-packages\django\core\management\__init__.py", line 375, in execute
    self.fetch_command(subcommand).run_from_argv(self.argv)
  File "C:\Users\Lenovo User\Desktop\Axsos\python_stack\my_environments\django_env\lib\site-packages\django\core\management\base.py", line 323, in run_from_argv
    self.execute(*args, **cmd_options)
  File "C:\Users\Lenovo User\Desktop\Axsos\python_stack\my_environments\django_env\lib\site-packages\django\core\management\base.py", line 361, in execute
    self.check()
  File "C:\Users\Lenovo User\Desktop\Axsos\python_stack\my_environments\django_env\lib\site-packages\django\core\management\base.py", line 390, in check
    include_deployment_checks=include_deployment_checks,
  File "C:\Users\Lenovo User\Desktop\Axsos\python_stack\my_environments\django_env\lib\site-packages\django\core\management\base.py", line 377, in _run_checks
    return checks.run_checks(**kwargs)
  File "C:\Users\Lenovo User\Desktop\Axsos\python_stack\my_environments\django_env\lib\site-packages\django\core\checks\registry.py", line 72, in run_checks
    new_errors = check(app_configs=app_configs)
  File "C:\Users\Lenovo User\Desktop\Axsos\python_stack\my_environments\django_env\lib\site-packages\django\core\checks\urls.py", line 13, in check_url_config
    return check_resolver(resolver)
  File "C:\Users\Lenovo User\Desktop\Axsos\python_stack\my_environments\django_env\lib\site-packages\django\core\checks\urls.py", line 23, in check_resolver
    return check_method()
  File "C:\Users\Lenovo User\Desktop\Axsos\python_stack\my_environments\django_env\lib\site-packages\django\urls\resolvers.py", line 398, in check
    for pattern in self.url_patterns:
  File "C:\Users\Lenovo User\Desktop\Axsos\python_stack\my_environments\django_env\lib\site-packages\django\utils\functional.py", line 80, in __get__
    res = instance.__dict__[self.name] = self.func(instance)
  File "C:\Users\Lenovo User\Desktop\Axsos\python_stack\my_environments\django_env\lib\site-packages\django\urls\resolvers.py", line 579, in url_patterns
    patterns = getattr(self.urlconf_module, "urlpatterns", self.urlconf_module)
  File "C:\Users\Lenovo User\Desktop\Axsos\python_stack\my_environments\django_env\lib\site-packages\django\utils\functional.py", line 80, in __get__
    res = instance.__dict__[self.name] = self.func(instance)
  File "C:\Users\Lenovo User\Desktop\Axsos\python_stack\my_environments\django_env\lib\site-packages\django\urls\resolvers.py", line 572, in urlconf_module
    return import_module(self.urlconf_name)
  File "C:\Users\Lenovo User\AppData\Local\Programs\Python\Python36\lib\importlib\__init__.py", line 126, in import_module
    return _bootstrap._gcd_import(name[level:], package, level)
  File "<frozen importlib._bootstrap>", line 994, in _gcd_import
  File "<frozen importlib._bootstrap>", line 971, in _find_and_load
  File "<frozen importlib._bootstrap>", line 955, in _find_and_load_unlocked
  File "<frozen importlib._bootstrap>", line 665, in _load_unlocked
  File "<frozen importlib._bootstrap_external>", line 678, in exec_module
  File "<frozen importlib._bootstrap>", line 219, in _call_with_frames_removed
  File "C:\Users\Lenovo User\Desktop\Axsos\python_stack\django\orm_project\orm_project\urls.py", line 20, in <module>
    path('admin/', orm_app.urls),
NameError: name 'orm_app' is not defined

(django_env) C:\Users\Lenovo User\Desktop\Axsos\python_stack\django\orm_project>python manage.py makemigrations \
Traceback (most recent call last):
  File "manage.py", line 21, in <module>
    main()
  File "manage.py", line 17, in main
    execute_from_command_line(sys.argv)
  File "C:\Users\Lenovo User\Desktop\Axsos\python_stack\my_environments\django_env\lib\site-packages\django\core\management\__init__.py", line 381, in execute_from_command_line
    utility.execute()
  File "C:\Users\Lenovo User\Desktop\Axsos\python_stack\my_environments\django_env\lib\site-packages\django\core\management\__init__.py", line 375, in execute
    self.fetch_command(subcommand).run_from_argv(self.argv)
  File "C:\Users\Lenovo User\Desktop\Axsos\python_stack\my_environments\django_env\lib\site-packages\django\core\management\base.py", line 323, in run_from_argv
    self.execute(*args, **cmd_options)
  File "C:\Users\Lenovo User\Desktop\Axsos\python_stack\my_environments\django_env\lib\site-packages\django\core\management\base.py", line 361, in execute
    self.check()
  File "C:\Users\Lenovo User\Desktop\Axsos\python_stack\my_environments\django_env\lib\site-packages\django\core\management\base.py", line 390, in check
    include_deployment_checks=include_deployment_checks,
  File "C:\Users\Lenovo User\Desktop\Axsos\python_stack\my_environments\django_env\lib\site-packages\django\core\management\base.py", line 377, in _run_checks
    return checks.run_checks(**kwargs)
  File "C:\Users\Lenovo User\Desktop\Axsos\python_stack\my_environments\django_env\lib\site-packages\django\core\checks\registry.py", line 72, in run_checks
    new_errors = check(app_configs=app_configs)
  File "C:\Users\Lenovo User\Desktop\Axsos\python_stack\my_environments\django_env\lib\site-packages\django\core\checks\urls.py", line 13, in check_url_config
    return check_resolver(resolver)
  File "C:\Users\Lenovo User\Desktop\Axsos\python_stack\my_environments\django_env\lib\site-packages\django\core\checks\urls.py", line 23, in check_resolver
    return check_method()
  File "C:\Users\Lenovo User\Desktop\Axsos\python_stack\my_environments\django_env\lib\site-packages\django\urls\resolvers.py", line 398, in check
    for pattern in self.url_patterns:
  File "C:\Users\Lenovo User\Desktop\Axsos\python_stack\my_environments\django_env\lib\site-packages\django\utils\functional.py", line 80, in __get__
    res = instance.__dict__[self.name] = self.func(instance)
  File "C:\Users\Lenovo User\Desktop\Axsos\python_stack\my_environments\django_env\lib\site-packages\django\urls\resolvers.py", line 579, in url_patterns
    patterns = getattr(self.urlconf_module, "urlpatterns", self.urlconf_module)
  File "C:\Users\Lenovo User\Desktop\Axsos\python_stack\my_environments\django_env\lib\site-packages\django\utils\functional.py", line 80, in __get__
    res = instance.__dict__[self.name] = self.func(instance)
  File "C:\Users\Lenovo User\Desktop\Axsos\python_stack\my_environments\django_env\lib\site-packages\django\urls\resolvers.py", line 572, in urlconf_module
    return import_module(self.urlconf_name)
  File "C:\Users\Lenovo User\AppData\Local\Programs\Python\Python36\lib\importlib\__init__.py", line 126, in import_module
    return _bootstrap._gcd_import(name[level:], package, level)
  File "<frozen importlib._bootstrap>", line 994, in _gcd_import
  File "<frozen importlib._bootstrap>", line 971, in _find_and_load
  File "<frozen importlib._bootstrap>", line 955, in _find_and_load_unlocked
  File "<frozen importlib._bootstrap>", line 665, in _load_unlocked
  File "<frozen importlib._bootstrap_external>", line 678, in exec_module
  File "<frozen importlib._bootstrap>", line 219, in _call_with_frames_removed
  File "C:\Users\Lenovo User\Desktop\Axsos\python_stack\django\orm_project\orm_project\urls.py", line 20, in <module>
    path('admin/', include ('orm_app.urls')),
NameError: name 'include' is not defined

(django_env) C:\Users\Lenovo User\Desktop\Axsos\python_stack\django\orm_project>python manage.py makemigrations \
Traceback (most recent call last):
  File "manage.py", line 21, in <module>
    main()
  File "manage.py", line 17, in main
    execute_from_command_line(sys.argv)
  File "C:\Users\Lenovo User\Desktop\Axsos\python_stack\my_environments\django_env\lib\site-packages\django\core\management\__init__.py", line 381, in execute_from_command_line
    utility.execute()
  File "C:\Users\Lenovo User\Desktop\Axsos\python_stack\my_environments\django_env\lib\site-packages\django\core\management\__init__.py", line 375, in execute
    self.fetch_command(subcommand).run_from_argv(self.argv)
  File "C:\Users\Lenovo User\Desktop\Axsos\python_stack\my_environments\django_env\lib\site-packages\django\core\management\base.py", line 323, in run_from_argv
    self.execute(*args, **cmd_options)
  File "C:\Users\Lenovo User\Desktop\Axsos\python_stack\my_environments\django_env\lib\site-packages\django\core\management\base.py", line 361, in execute
    self.check()
  File "C:\Users\Lenovo User\Desktop\Axsos\python_stack\my_environments\django_env\lib\site-packages\django\core\management\base.py", line 390, in check
    include_deployment_checks=include_deployment_checks,
  File "C:\Users\Lenovo User\Desktop\Axsos\python_stack\my_environments\django_env\lib\site-packages\django\core\management\base.py", line 377, in _run_checks
    return checks.run_checks(**kwargs)
  File "C:\Users\Lenovo User\Desktop\Axsos\python_stack\my_environments\django_env\lib\site-packages\django\core\checks\registry.py", line 72, in run_checks
    new_errors = check(app_configs=app_configs)
  File "C:\Users\Lenovo User\Desktop\Axsos\python_stack\my_environments\django_env\lib\site-packages\django\core\checks\urls.py", line 13, in check_url_config
    return check_resolver(resolver)
  File "C:\Users\Lenovo User\Desktop\Axsos\python_stack\my_environments\django_env\lib\site-packages\django\core\checks\urls.py", line 23, in check_resolver
    return check_method()
  File "C:\Users\Lenovo User\Desktop\Axsos\python_stack\my_environments\django_env\lib\site-packages\django\urls\resolvers.py", line 398, in check
    for pattern in self.url_patterns:
  File "C:\Users\Lenovo User\Desktop\Axsos\python_stack\my_environments\django_env\lib\site-packages\django\utils\functional.py", line 80, in __get__
    res = instance.__dict__[self.name] = self.func(instance)
  File "C:\Users\Lenovo User\Desktop\Axsos\python_stack\my_environments\django_env\lib\site-packages\django\urls\resolvers.py", line 579, in url_patterns
    patterns = getattr(self.urlconf_module, "urlpatterns", self.urlconf_module)
  File "C:\Users\Lenovo User\Desktop\Axsos\python_stack\my_environments\django_env\lib\site-packages\django\utils\functional.py", line 80, in __get__
    res = instance.__dict__[self.name] = self.func(instance)
  File "C:\Users\Lenovo User\Desktop\Axsos\python_stack\my_environments\django_env\lib\site-packages\django\urls\resolvers.py", line 572, in urlconf_module
    return import_module(self.urlconf_name)
  File "C:\Users\Lenovo User\AppData\Local\Programs\Python\Python36\lib\importlib\__init__.py", line 126, in import_module
    return _bootstrap._gcd_import(name[level:], package, level)
  File "<frozen importlib._bootstrap>", line 994, in _gcd_import
  File "<frozen importlib._bootstrap>", line 971, in _find_and_load
  File "<frozen importlib._bootstrap>", line 955, in _find_and_load_unlocked
  File "<frozen importlib._bootstrap>", line 665, in _load_unlocked
  File "<frozen importlib._bootstrap_external>", line 674, in exec_module
  File "<frozen importlib._bootstrap_external>", line 781, in get_code
  File "<frozen importlib._bootstrap_external>", line 741, in source_to_code
  File "<frozen importlib._bootstrap>", line 219, in _call_with_frames_removed
  File "C:\Users\Lenovo User\Desktop\Axsos\python_stack\django\orm_project\orm_project\urls.py", line 4
    path('', include('orm_app.urls')),
                                     ^
SyntaxError: unexpected EOF while parsing

(django_env) C:\Users\Lenovo User\Desktop\Axsos\python_stack\django\orm_project>python manage.py makemigrations \
Traceback (most recent call last):
  File "C:\Users\Lenovo User\Desktop\Axsos\python_stack\my_environments\django_env\lib\site-packages\django\urls\resolvers.py", line 581, in url_patterns
    iter(patterns)
TypeError: 'module' object is not iterable

During handling of the above exception, another exception occurred:

Traceback (most recent call last):
  File "manage.py", line 21, in <module>
    main()
  File "manage.py", line 17, in main
    execute_from_command_line(sys.argv)
  File "C:\Users\Lenovo User\Desktop\Axsos\python_stack\my_environments\django_env\lib\site-packages\django\core\management\__init__.py", line 381, in execute_from_command_line
    utility.execute()
  File "C:\Users\Lenovo User\Desktop\Axsos\python_stack\my_environments\django_env\lib\site-packages\django\core\management\__init__.py", line 375, in execute
    self.fetch_command(subcommand).run_from_argv(self.argv)
  File "C:\Users\Lenovo User\Desktop\Axsos\python_stack\my_environments\django_env\lib\site-packages\django\core\management\base.py", line 323, in run_from_argv
    self.execute(*args, **cmd_options)
  File "C:\Users\Lenovo User\Desktop\Axsos\python_stack\my_environments\django_env\lib\site-packages\django\core\management\base.py", line 361, in execute
    self.check()
  File "C:\Users\Lenovo User\Desktop\Axsos\python_stack\my_environments\django_env\lib\site-packages\django\core\management\base.py", line 390, in check
    include_deployment_checks=include_deployment_checks,
  File "C:\Users\Lenovo User\Desktop\Axsos\python_stack\my_environments\django_env\lib\site-packages\django\core\management\base.py", line 377, in _run_checks
    return checks.run_checks(**kwargs)
  File "C:\Users\Lenovo User\Desktop\Axsos\python_stack\my_environments\django_env\lib\site-packages\django\core\checks\registry.py", line 72, in run_checks
    new_errors = check(app_configs=app_configs)
  File "C:\Users\Lenovo User\Desktop\Axsos\python_stack\my_environments\django_env\lib\site-packages\django\core\checks\urls.py", line 13, in check_url_config
    return check_resolver(resolver)
  File "C:\Users\Lenovo User\Desktop\Axsos\python_stack\my_environments\django_env\lib\site-packages\django\core\checks\urls.py", line 23, in check_resolver
    return check_method()
  File "C:\Users\Lenovo User\Desktop\Axsos\python_stack\my_environments\django_env\lib\site-packages\django\urls\resolvers.py", line 399, in check
    messages.extend(check_resolver(pattern))
  File "C:\Users\Lenovo User\Desktop\Axsos\python_stack\my_environments\django_env\lib\site-packages\django\core\checks\urls.py", line 23, in check_resolver
    return check_method()
  File "C:\Users\Lenovo User\Desktop\Axsos\python_stack\my_environments\django_env\lib\site-packages\django\urls\resolvers.py", line 398, in check
    for pattern in self.url_patterns:
  File "C:\Users\Lenovo User\Desktop\Axsos\python_stack\my_environments\django_env\lib\site-packages\django\utils\functional.py", line 80, in __get__
    res = instance.__dict__[self.name] = self.func(instance)
  File "C:\Users\Lenovo User\Desktop\Axsos\python_stack\my_environments\django_env\lib\site-packages\django\urls\resolvers.py", line 588, in url_patterns
    raise ImproperlyConfigured(msg.format(name=self.urlconf_name))
django.core.exceptions.ImproperlyConfigured: The included URLconf '<module 'orm_app.urls' from 'C:\\Users\\Lenovo User\\Desktop\\Axsos\\python_stack\\django\\orm_project\\orm_app\\urls.py'>' does not appear to have any patterns in it. If you see valid patterns in the file then the issue is probably caused by a circular import.

(django_env) C:\Users\Lenovo User\Desktop\Axsos\python_stack\django\orm_project>python manage.py makemigrations \
Traceback (most recent call last):
  File "C:\Users\Lenovo User\Desktop\Axsos\python_stack\my_environments\django_env\lib\site-packages\django\urls\resolvers.py", line 581, in url_patterns
    iter(patterns)
TypeError: 'module' object is not iterable

During handling of the above exception, another exception occurred:

Traceback (most recent call last):
  File "manage.py", line 21, in <module>
    main()
  File "manage.py", line 17, in main
    execute_from_command_line(sys.argv)
  File "C:\Users\Lenovo User\Desktop\Axsos\python_stack\my_environments\django_env\lib\site-packages\django\core\management\__init__.py", line 381, in execute_from_command_line
    utility.execute()
  File "C:\Users\Lenovo User\Desktop\Axsos\python_stack\my_environments\django_env\lib\site-packages\django\core\management\__init__.py", line 375, in execute
    self.fetch_command(subcommand).run_from_argv(self.argv)
  File "C:\Users\Lenovo User\Desktop\Axsos\python_stack\my_environments\django_env\lib\site-packages\django\core\management\base.py", line 323, in run_from_argv
    self.execute(*args, **cmd_options)
  File "C:\Users\Lenovo User\Desktop\Axsos\python_stack\my_environments\django_env\lib\site-packages\django\core\management\base.py", line 361, in execute
    self.check()
  File "C:\Users\Lenovo User\Desktop\Axsos\python_stack\my_environments\django_env\lib\site-packages\django\core\management\base.py", line 390, in check
    include_deployment_checks=include_deployment_checks,
  File "C:\Users\Lenovo User\Desktop\Axsos\python_stack\my_environments\django_env\lib\site-packages\django\core\management\base.py", line 377, in _run_checks
    return checks.run_checks(**kwargs)
  File "C:\Users\Lenovo User\Desktop\Axsos\python_stack\my_environments\django_env\lib\site-packages\django\core\checks\registry.py", line 72, in run_checks
    new_errors = check(app_configs=app_configs)
  File "C:\Users\Lenovo User\Desktop\Axsos\python_stack\my_environments\django_env\lib\site-packages\django\core\checks\urls.py", line 13, in check_url_config
    return check_resolver(resolver)
  File "C:\Users\Lenovo User\Desktop\Axsos\python_stack\my_environments\django_env\lib\site-packages\django\core\checks\urls.py", line 23, in check_resolver
    return check_method()
  File "C:\Users\Lenovo User\Desktop\Axsos\python_stack\my_environments\django_env\lib\site-packages\django\urls\resolvers.py", line 399, in check
    messages.extend(check_resolver(pattern))
  File "C:\Users\Lenovo User\Desktop\Axsos\python_stack\my_environments\django_env\lib\site-packages\django\core\checks\urls.py", line 23, in check_resolver
    return check_method()
  File "C:\Users\Lenovo User\Desktop\Axsos\python_stack\my_environments\django_env\lib\site-packages\django\urls\resolvers.py", line 398, in check
    for pattern in self.url_patterns:
  File "C:\Users\Lenovo User\Desktop\Axsos\python_stack\my_environments\django_env\lib\site-packages\django\utils\functional.py", line 80, in __get__
    res = instance.__dict__[self.name] = self.func(instance)
  File "C:\Users\Lenovo User\Desktop\Axsos\python_stack\my_environments\django_env\lib\site-packages\django\urls\resolvers.py", line 588, in url_patterns
    raise ImproperlyConfigured(msg.format(name=self.urlconf_name))
django.core.exceptions.ImproperlyConfigured: The included URLconf '<module 'orm_app.urls' from 'C:\\Users\\Lenovo User\\Desktop\\Axsos\\python_stack\\django\\orm_project\\orm_app\\urls.py'>' does not appear to have any patterns in it. If you see valid patterns in the file then the issue is probably caused by a circular import.

(django_env) C:\Users\Lenovo User\Desktop\Axsos\python_stack\django\orm_project>]
']' is not recognized as an internal or external command,
operable program or batch file.

(django_env) C:\Users\Lenovo User\Desktop\Axsos\python_stack\django\orm_project>python manage.py makemigrations
Traceback (most recent call last):
  File "C:\Users\Lenovo User\Desktop\Axsos\python_stack\my_environments\django_env\lib\site-packages\django\urls\resolvers.py", line 581, in url_patterns
    iter(patterns)
TypeError: 'module' object is not iterable

During handling of the above exception, another exception occurred:

Traceback (most recent call last):
  File "manage.py", line 21, in <module>
    main()
  File "manage.py", line 17, in main
    execute_from_command_line(sys.argv)
  File "C:\Users\Lenovo User\Desktop\Axsos\python_stack\my_environments\django_env\lib\site-packages\django\core\management\__init__.py", line 381, in execute_from_command_line
    utility.execute()
  File "C:\Users\Lenovo User\Desktop\Axsos\python_stack\my_environments\django_env\lib\site-packages\django\core\management\__init__.py", line 375, in execute
    self.fetch_command(subcommand).run_from_argv(self.argv)
  File "C:\Users\Lenovo User\Desktop\Axsos\python_stack\my_environments\django_env\lib\site-packages\django\core\management\base.py", line 323, in run_from_argv
    self.execute(*args, **cmd_options)
  File "C:\Users\Lenovo User\Desktop\Axsos\python_stack\my_environments\django_env\lib\site-packages\django\core\management\base.py", line 361, in execute
    self.check()
  File "C:\Users\Lenovo User\Desktop\Axsos\python_stack\my_environments\django_env\lib\site-packages\django\core\management\base.py", line 390, in check
    include_deployment_checks=include_deployment_checks,
  File "C:\Users\Lenovo User\Desktop\Axsos\python_stack\my_environments\django_env\lib\site-packages\django\core\management\base.py", line 377, in _run_checks
    return checks.run_checks(**kwargs)
  File "C:\Users\Lenovo User\Desktop\Axsos\python_stack\my_environments\django_env\lib\site-packages\django\core\checks\registry.py", line 72, in run_checks
    new_errors = check(app_configs=app_configs)
  File "C:\Users\Lenovo User\Desktop\Axsos\python_stack\my_environments\django_env\lib\site-packages\django\core\checks\urls.py", line 13, in check_url_config
    return check_resolver(resolver)
  File "C:\Users\Lenovo User\Desktop\Axsos\python_stack\my_environments\django_env\lib\site-packages\django\core\checks\urls.py", line 23, in check_resolver
    return check_method()
  File "C:\Users\Lenovo User\Desktop\Axsos\python_stack\my_environments\django_env\lib\site-packages\django\urls\resolvers.py", line 399, in check
    messages.extend(check_resolver(pattern))
  File "C:\Users\Lenovo User\Desktop\Axsos\python_stack\my_environments\django_env\lib\site-packages\django\core\checks\urls.py", line 23, in check_resolver
    return check_method()
  File "C:\Users\Lenovo User\Desktop\Axsos\python_stack\my_environments\django_env\lib\site-packages\django\urls\resolvers.py", line 398, in check
    for pattern in self.url_patterns:
  File "C:\Users\Lenovo User\Desktop\Axsos\python_stack\my_environments\django_env\lib\site-packages\django\utils\functional.py", line 80, in __get__
    res = instance.__dict__[self.name] = self.func(instance)
  File "C:\Users\Lenovo User\Desktop\Axsos\python_stack\my_environments\django_env\lib\site-packages\django\urls\resolvers.py", line 588, in url_patterns
    raise ImproperlyConfigured(msg.format(name=self.urlconf_name))
django.core.exceptions.ImproperlyConfigured: The included URLconf '<module 'orm_app.urls' from 'C:\\Users\\Lenovo User\\Desktop\\Axsos\\python_stack\\django\\orm_project\\orm_app\\urls.py'>' does not appear to have any patterns in it. If you see valid patterns in the file then the issue is probably caused by a circular import.

(django_env) C:\Users\Lenovo User\Desktop\Axsos\python_stack\django\orm_project>python manage.py makemigrations
Traceback (most recent call last):
  File "manage.py", line 21, in <module>
    main()
  File "manage.py", line 17, in main
    execute_from_command_line(sys.argv)
  File "C:\Users\Lenovo User\Desktop\Axsos\python_stack\my_environments\django_env\lib\site-packages\django\core\management\__init__.py", line 381, in execute_from_command_line
    utility.execute()
  File "C:\Users\Lenovo User\Desktop\Axsos\python_stack\my_environments\django_env\lib\site-packages\django\core\management\__init__.py", line 375, in execute
    self.fetch_command(subcommand).run_from_argv(self.argv)
  File "C:\Users\Lenovo User\Desktop\Axsos\python_stack\my_environments\django_env\lib\site-packages\django\core\management\base.py", line 323, in run_from_argv
    self.execute(*args, **cmd_options)
  File "C:\Users\Lenovo User\Desktop\Axsos\python_stack\my_environments\django_env\lib\site-packages\django\core\management\base.py", line 361, in execute
    self.check()
  File "C:\Users\Lenovo User\Desktop\Axsos\python_stack\my_environments\django_env\lib\site-packages\django\core\management\base.py", line 390, in check
    include_deployment_checks=include_deployment_checks,
  File "C:\Users\Lenovo User\Desktop\Axsos\python_stack\my_environments\django_env\lib\site-packages\django\core\management\base.py", line 377, in _run_checks
    return checks.run_checks(**kwargs)
  File "C:\Users\Lenovo User\Desktop\Axsos\python_stack\my_environments\django_env\lib\site-packages\django\core\checks\registry.py", line 72, in run_checks
    new_errors = check(app_configs=app_configs)
  File "C:\Users\Lenovo User\Desktop\Axsos\python_stack\my_environments\django_env\lib\site-packages\django\core\checks\urls.py", line 13, in check_url_config
    return check_resolver(resolver)
  File "C:\Users\Lenovo User\Desktop\Axsos\python_stack\my_environments\django_env\lib\site-packages\django\core\checks\urls.py", line 23, in check_resolver
    return check_method()
  File "C:\Users\Lenovo User\Desktop\Axsos\python_stack\my_environments\django_env\lib\site-packages\django\urls\resolvers.py", line 398, in check
    for pattern in self.url_patterns:
  File "C:\Users\Lenovo User\Desktop\Axsos\python_stack\my_environments\django_env\lib\site-packages\django\utils\functional.py", line 80, in __get__
    res = instance.__dict__[self.name] = self.func(instance)
  File "C:\Users\Lenovo User\Desktop\Axsos\python_stack\my_environments\django_env\lib\site-packages\django\urls\resolvers.py", line 579, in url_patterns
    patterns = getattr(self.urlconf_module, "urlpatterns", self.urlconf_module)
  File "C:\Users\Lenovo User\Desktop\Axsos\python_stack\my_environments\django_env\lib\site-packages\django\utils\functional.py", line 80, in __get__
    res = instance.__dict__[self.name] = self.func(instance)
  File "C:\Users\Lenovo User\Desktop\Axsos\python_stack\my_environments\django_env\lib\site-packages\django\urls\resolvers.py", line 572, in urlconf_module
    return import_module(self.urlconf_name)
  File "C:\Users\Lenovo User\AppData\Local\Programs\Python\Python36\lib\importlib\__init__.py", line 126, in import_module
    return _bootstrap._gcd_import(name[level:], package, level)
  File "<frozen importlib._bootstrap>", line 994, in _gcd_import
  File "<frozen importlib._bootstrap>", line 971, in _find_and_load
  File "<frozen importlib._bootstrap>", line 955, in _find_and_load_unlocked
  File "<frozen importlib._bootstrap>", line 665, in _load_unlocked
  File "<frozen importlib._bootstrap_external>", line 678, in exec_module
  File "<frozen importlib._bootstrap>", line 219, in _call_with_frames_removed
  File "C:\Users\Lenovo User\Desktop\Axsos\python_stack\django\orm_project\orm_project\urls.py", line 3, in <module>
    path('', include('orm_app.urls')),]
  File "C:\Users\Lenovo User\Desktop\Axsos\python_stack\my_environments\django_env\lib\site-packages\django\urls\conf.py", line 34, in include
    urlconf_module = import_module(urlconf_module)
  File "C:\Users\Lenovo User\AppData\Local\Programs\Python\Python36\lib\importlib\__init__.py", line 126, in import_module
    return _bootstrap._gcd_import(name[level:], package, level)
  File "<frozen importlib._bootstrap>", line 994, in _gcd_import
  File "<frozen importlib._bootstrap>", line 971, in _find_and_load
  File "<frozen importlib._bootstrap>", line 953, in _find_and_load_unlocked
ModuleNotFoundError: No module named 'orm_app.urls'

(django_env) C:\Users\Lenovo User\Desktop\Axsos\python_stack\django\orm_project>python manage.py makemigrations
Migrations for 'orm_app':
  orm_app\migrations\0001_initial.py
    - Create model Movie

(django_env) C:\Users\Lenovo User\Desktop\Axsos\python_stack\django\orm_project>python class users(models.Model):
python: can't open file 'class': [Errno 2] No such file or directory

(django_env) C:\Users\Lenovo User\Desktop\Axsos\python_stack\django\orm_project>    first_name = models.CharField(max_length=255)
'first_name' is not recognized as an internal or external command,
operable program or batch file.

(django_env) C:\Users\Lenovo User\Desktop\Axsos\python_stack\django\orm_project>    last_name = models.CharField(max_length=255)
'last_name' is not recognized as an internal or external command,
operable program or batch file.

(django_env) C:\Users\Lenovo User\Desktop\Axsos\python_stack\django\orm_project>    email_address = models.CharField(max_length=255)
'email_address' is not recognized as an internal or external command,
operable program or batch file.

(django_env) C:\Users\Lenovo User\Desktop\Axsos\python_stack\django\orm_project>    age = models.IntegerField()
'age' is not recognized as an internal or external command,
operable program or batch file.

(django_env) C:\Users\Lenovo User\Desktop\Axsos\python_stack\django\orm_project>    created_at = models.DateTimeField(auto_now_add=True)
'created_at' is not recognized as an internal or external command,
operable program or batch file.

(django_env) C:\Users\Lenovo User\Desktop\Axsos\python_stack\django\orm_project>    updated_at = models.DateTimeField(auto_n

(django_env) C:\Users\Lenovo User\Desktop\Axsos\python_stack\django\orm_project>class users(models.Model):
'class' is not recognized as an internal or external command,
operable program or batch file.

(django_env) C:\Users\Lenovo User\Desktop\Axsos\python_stack\django\orm_project>    first_name = models.CharField(max_length=255)
'first_name' is not recognized as an internal or external command,
operable program or batch file.

(django_env) C:\Users\Lenovo User\Desktop\Axsos\python_stack\django\orm_project>    last_name = models.CharField(max_length=255)
'last_name' is not recognized as an internal or external command,
operable program or batch file.

(django_env) C:\Users\Lenovo User\Desktop\Axsos\python_stack\django\orm_project>    email_address = models.CharField(max_length=255)
'email_address' is not recognized as an internal or external command,
operable program or batch file.

(django_env) C:\Users\Lenovo User\Desktop\Axsos\python_stack\django\orm_project>    age = models.IntegerField()
'age' is not recognized as an internal or external command,
operable program or batch file.

(django_env) C:\Users\Lenovo User\Desktop\Axsos\python_stack\django\orm_project>    created_at = models.DateTimeField(auto_now_add=True)
'created_at' is not recognized as an internal or external command,
operable program or batch file.

(django_env) C:\Users\Lenovo User\Desktop\Axsos\python_stack\django\orm_project>    updated_at = models.DateTimeField(auto_now=True)

(django_env) C:\Users\Lenovo User\Desktop\Axsos\python_stack\django\orm_project>python manage.py migrate

(django_env) C:\Users\Lenovo User\Desktop\Axsos\python_stack\django\orm_project>python manage.py makemigrations
Traceback (most recent call last):
  File "manage.py", line 21, in <module>
    main()
  File "manage.py", line 17, in main
    execute_from_command_line(sys.argv)
  File "C:\Users\Lenovo User\Desktop\Axsos\python_stack\my_environments\django_env\lib\site-packages\django\core\management\__init__.py", line 381, in execute_from_command_line
    utility.execute()
  File "C:\Users\Lenovo User\Desktop\Axsos\python_stack\my_environments\django_env\lib\site-packages\django\core\management\__init__.py", line 357, in execute
    django.setup()
  File "C:\Users\Lenovo User\Desktop\Axsos\python_stack\my_environments\django_env\lib\site-packages\django\__init__.py", line 24, in setup
    apps.populate(settings.INSTALLED_APPS)
  File "C:\Users\Lenovo User\Desktop\Axsos\python_stack\my_environments\django_env\lib\site-packages\django\apps\registry.py", line 114, in populate
    app_config.import_models()
  File "C:\Users\Lenovo User\Desktop\Axsos\python_stack\my_environments\django_env\lib\site-packages\django\apps\config.py", line 211, in import_models
    self.models_module = import_module(models_module_name)
  File "C:\Users\Lenovo User\AppData\Local\Programs\Python\Python36\lib\importlib\__init__.py", line 126, in import_module
    return _bootstrap._gcd_import(name[level:], package, level)
  File "<frozen importlib._bootstrap>", line 994, in _gcd_import
  File "<frozen importlib._bootstrap>", line 971, in _find_and_load
  File "<frozen importlib._bootstrap>", line 955, in _find_and_load_unlocked
  File "<frozen importlib._bootstrap>", line 665, in _load_unlocked
  File "<frozen importlib._bootstrap_external>", line 678, in exec_module
  File "<frozen importlib._bootstrap>", line 219, in _call_with_frames_removed
  File "C:\Users\Lenovo User\Desktop\Axsos\python_stack\django\orm_project\orm_app\models.py", line 1, in <module>
    class users(models.Model):
NameError: name 'models' is not defined

(django_env) C:\Users\Lenovo User\Desktop\Axsos\python_stack\django\orm_project>python manage.py makemigrations
Migrations for 'orm_app':
  orm_app\migrations\0002_auto_20210520_1137.py
    - Create model users
    - Delete model Movie

(django_env) C:\Users\Lenovo User\Desktop\Axsos\python_stack\django\orm_project>python manage.py mirgate
Unknown command: 'mirgate'. Did you mean migrate?
Type 'manage.py help' for usage.

(django_env) C:\Users\Lenovo User\Desktop\Axsos\python_stack\django\orm_project>python manage.py mirgrate
Unknown command: 'mirgrate'. Did you mean migrate?
Type 'manage.py help' for usage.

(django_env) C:\Users\Lenovo User\Desktop\Axsos\python_stack\django\orm_project>python manage.py migrate
Operations to perform:
  Apply all migrations: admin, auth, contenttypes, orm_app, sessions
Running migrations:
  Applying contenttypes.0001_initial... OK
  Applying auth.0001_initial... OK
  Applying admin.0001_initial... OK
  Applying admin.0002_logentry_remove_auto_add... OK
  Applying admin.0003_logentry_add_action_flag_choices... OK
  Applying contenttypes.0002_remove_content_type_name... OK
  Applying auth.0002_alter_permission_name_max_length... OK
  Applying auth.0003_alter_user_email_max_length... OK
  Applying auth.0004_alter_user_username_opts... OK
  Applying auth.0005_alter_user_last_login_null... OK
  Applying auth.0006_require_contenttypes_0002... OK
  Applying auth.0007_alter_validators_add_error_messages... OK
  Applying auth.0008_alter_user_username_max_length... OK
  Applying auth.0009_alter_user_last_name_max_length... OK
  Applying auth.0010_alter_group_name_max_length... OK
  Applying auth.0011_update_proxy_permissions... OK
  Applying orm_app.0001_initial... OK
  Applying orm_app.0002_auto_20210520_1137... OK
  Applying sessions.0001_initial... OK

(django_env) C:\Users\Lenovo User\Desktop\Axsos\python_stack\django\orm_project>python manage.py shell
Python 3.6.4 (v3.6.4:d48eceb, Dec 19 2017, 06:54:40) [MSC v.1900 64 bit (AMD64)] on win32
Type "help", "copyright", "credits" or "license" for more information.
(InteractiveConsole)
>>> from orm_app.models import *
>>> users.objects.create
<bound method BaseManager._get_queryset_methods.<locals>.create_method.<locals>.manager_method of <django.db.models.manager.Manager object at 0x00000211ED0FBB38>>
>>> users.objects.create(fisrt_name="amro", last_name="hashsesh",email_address="momama@org.com",age="20")
Traceback (most recent call last):
  File "<console>", line 1, in <module>
  File "C:\Users\Lenovo User\Desktop\Axsos\python_stack\my_environments\django_env\lib\site-packages\django\db\models\manager.py", line 82, in manager_method
    return getattr(self.get_queryset(), name)(*args, **kwargs)
  File "C:\Users\Lenovo User\Desktop\Axsos\python_stack\my_environments\django_env\lib\site-packages\django\db\models\query.py", line 420, in create
    obj = self.model(**kwargs)
  File "C:\Users\Lenovo User\Desktop\Axsos\python_stack\my_environments\django_env\lib\site-packages\django\db\models\base.py", line 501, in __init__
    raise TypeError("%s() got an unexpected keyword argument '%s'" % (cls.__name__, kwarg))
TypeError: users() got an unexpected keyword argument 'fisrt_name'
>>> users.objects.create(first_name="amro", last_name="hashsesh",email_address="momama@org.com",age="20")
<users: users object (1)>
>>> users.objects.create(first_name="mohaamd", last_name="habib",email_address="amri#@akskak.com",age="23")
<users: users object (2)>
>>> users.objects.create(fisrt_name="shehhn", last_name="seaad",email_address="esasa_momama@org.com",age="26")
Traceback (most recent call last):
  File "<console>", line 1, in <module>
  File "C:\Users\Lenovo User\Desktop\Axsos\python_stack\my_environments\django_env\lib\site-packages\django\db\models\manager.py", line 82, in manager_method
    return getattr(self.get_queryset(), name)(*args, **kwargs)
  File "C:\Users\Lenovo User\Desktop\Axsos\python_stack\my_environments\django_env\lib\site-packages\django\db\models\query.py", line 420, in create
    obj = self.model(**kwargs)
  File "C:\Users\Lenovo User\Desktop\Axsos\python_stack\my_environments\django_env\lib\site-packages\django\db\models\base.py", line 501, in __init__
    raise TypeError("%s() got an unexpected keyword argument '%s'" % (cls.__name__, kwarg))
TypeError: users() got an unexpected keyword argument 'fisrt_name'
>>> users.objects.create(first_name="shehhn", last_name="seaad",email_address="esasa_momama@org.com",age="26")
<users: users object (3)>
>>> users.objects.all()
<QuerySet [<users: users object (1)>, <users: users object (2)>, <users: users object (3)>]>
>>> users.objects.all().values
<bound method QuerySet.values of <QuerySet [<users: users object (1)>, <users: users object (2)>, <users: users object (3)>]>>
>>> users.objects.all().values()
<QuerySet [{'id': 1, 'first_name': 'amro', 'last_name': 'hashsesh', 'email_address': 'momama@org.com', 'age': 20, 'created_at': datetime.datetime(2021, 5, 20, 8, 47, 31, 506234, tzinfo=<UTC>), 'updated_at': datetime.datetime(2021, 5, 20, 8, 47, 31, 506234, tzinfo=<UTC>)}, {'id': 2, 'first_name': 'mohaamd', 'last_name': 'habib', 'email_address': 'amri#@akskak.com', 'age': 23, 'created_at': datetime.datetime(2021, 5, 20, 8, 48, 35, 807229, tzinfo=<UTC>), 'updated_at': datetime.datetime(2021, 5, 20, 8, 48, 35, 807229, tzinfo=<UTC>)}, {'id': 3, 'first_name': 'shehhn', 'last_name': 'seaad', 'email_address': 'esasa_momama@org.com', 'age': 26, 'created_at': datetime.datetime(2021, 5, 20, 8, 49, 33, 279086, tzinfo=<UTC>), 'updated_at': datetime.datetime(2021, 5, 20, 8, 49, 33, 279086, tzinfo=<UTC>)}]>
>>> users.objects.first()
<users: users object (1)>
>>> users.objects.first().__dict__
{'_state': <django.db.models.base.ModelState object at 0x00000211ED18A588>, 'id': 1, 'first_name': 'amro', 'last_name': 'hashsesh', 'email_address': 'momama@org.com', 'age': 20, 'created_at': datetime.datetime(2021, 5, 20, 8, 47, 31, 506234, tzinfo=<UTC>), 'updated_at': datetime.datetime(2021, 5, 20, 8, 47, 31, 506234, tzinfo=<UTC>)}
>>> users.objects.last().__dict__
{'_state': <django.db.models.base.ModelState object at 0x00000211ED18A630>, 'id': 3, 'first_name': 'shehhn', 'last_name': 'seaad', 'email_address': 'esasa_momama@org.com', 'age': 26, 'created_at': datetime.datetime(2021, 5, 20, 8, 49, 33, 279086, tzinfo=<UTC>), 'updated_at': datetime.datetime(2021, 5, 20, 8, 49, 33, 279086, tzinfo=<UTC>)}
>>> b=users.objects.last()
>>> b.last_name = "pancakes"
>>> b.save
<bound method Model.save of <users: users object (3)>>
>>> users.objects.all()
<QuerySet [<users: users object (1)>, <users: users object (2)>, <users: users object (3)>]>
>>> users.objects.all().values()
<QuerySet [{'id': 1, 'first_name': 'amro', 'last_name': 'hashsesh', 'email_address': 'momama@org.com', 'age': 20, 'created_at': datetime.datetime(2021, 5, 20, 8, 47, 31, 506234, tzinfo=<UTC>), 'updated_at': datetime.datetime(2021, 5, 20, 8, 47, 31, 506234, tzinfo=<UTC>)}, {'id': 2, 'first_name': 'mohaamd', 'last_name': 'habib', 'email_address': 'amri#@akskak.com', 'age': 23, 'created_at': datetime.datetime(2021, 5, 20, 8, 48, 35, 807229, tzinfo=<UTC>), 'updated_at': datetime.datetime(2021, 5, 20, 8, 48, 35, 807229, tzinfo=<UTC>)}, {'id': 3, 'first_name': 'shehhn', 'last_name': 'seaad', 'email_address': 'esasa_momama@org.com', 'age': 26, 'created_at': datetime.datetime(2021, 5, 20, 8, 49, 33, 279086, tzinfo=<UTC>), 'updated_at': datetime.datetime(2021, 5, 20, 8, 49, 33, 279086, tzinfo=<UTC>)}]>
>>> users.objects.last
<bound method BaseManager._get_queryset_methods.<locals>.create_method.<locals>.manager_method of <django.db.models.manager.Manager object at 0x00000211ED0FBB38>>
>>> users.objects.last()
<users: users object (3)>
>>> users.objects.last().__dict__
{'_state': <django.db.models.base.ModelState object at 0x00000211ED18A898>, 'id': 3, 'first_name': 'shehhn', 'last_name': 'seaad', 'email_address': 'esasa_momama@org.com', 'age': 26, 'created_at': datetime.datetime(2021, 5, 20, 8, 49, 33, 279086, tzinfo=<UTC>), 'updated_at': datetime.datetime(2021, 5, 20, 8, 49, 33, 279086, tzinfo=<UTC>)}
>>> b.save()
>>> users.objects.last().__dict__
{'_state': <django.db.models.base.ModelState object at 0x00000211ED18AA20>, 'id': 3, 'first_name': 'shehhn', 'last_name': 'pancakes', 'email_address': 'esasa_momama@org.com', 'age': 26, 'created_at': datetime.datetime(2021, 5, 20, 8, 49, 33, 279086, tzinfo=<UTC>), 'updated_at': datetime.datetime(2021, 5, 20, 8, 59, 27, 510156, tzinfo=<UTC>)}
>>> users.objects.get(id=2)
<users: users object (2)>
>>> users.delete()
Traceback (most recent call last):
  File "<console>", line 1, in <module>
TypeError: delete() missing 1 required positional argument: 'self'
>>> users.objects.delete()
Traceback (most recent call last):
  File "<console>", line 1, in <module>
AttributeError: 'Manager' object has no attribute 'delete'
>>> users.objects.get(id=2)
<users: users object (2)>
>>> c=users.objects.get(id=2)
>>> c.delete()
(1, {'orm_app.users': 1})
>>> users.objects.all()
<QuerySet [<users: users object (1)>, <users: users object (3)>]>
>>> users.objects.all().order_by("first_name")
<QuerySet [<users: users object (1)>, <users: users object (3)>]>
>>> users.objects.all().order_by("first_name").__dict__
{'model': <class 'orm_app.models.users'>, '_db': None, '_hints': {}, 'query': <django.db.models.sql.query.Query object at 0x00000211ED17EB38>, '_result_cache': None, '_sticky_filter': False, '_for_write': False, '_prefetch_related_lookups': (), '_prefetch_done': False, '_known_related_objects': {}, '_iterable_class': <class 'django.db.models.query.ModelIterable'>, '_fields': None}
>>> users.objects.all().order_by("first_name").value()
Traceback (most recent call last):
  File "<console>", line 1, in <module>
AttributeError: 'QuerySet' object has no attribute 'value'
>>> users.objects.all().order_by("first_name")
<QuerySet [<users: users object (1)>, <users: users object (3)>]>
>>>